Workbook
Name Cod_clienti: #REF!
Name Cod_clienti: #REF!
Name Elenco0_1: #REF!
Name Elenco0_1: #REF!
Name Elenco0_7: #REF!
Name Elenco0_7: #REF!
Name TipoCorsa: #REF!
Name TipoCorsa: #REF!
Name TipoCorsa_7: #REF!
Name TipoCorsa_7: #REF!
Name VanoMet: #REF!
Name VanoMet: #REF!

Sheet Facile Step SRC
B2: FACILE STEP (SRC rettilineo) | G2: N° OFFERTA | H2: #VALUE!
B5: DESCRIZIONE
B6: Piattaforma 840x650 ribaltabile manualmente, bandelle mobili automatiche, dispositivi di sicurezza | F6: 8287.5 | G6: 1 | H6: =F6*G6 -> 8287.5
B7: GUIDA
B8: Ogni alzata della scala | D8: Numero | F8: 75 | H8: =F8*G8 -> 0
B9: Ogni metro di guida (alzate fuori standard, rampe, ecc.) | D9: Metri | F9: 225 | H9: =F9*G9 -> 0
B10: Extra guida zincata per esterni in cataforesi (suppl. PER ALZATA) | D10: Numero | F10: 30 | H10: =F10*G10 -> 0
B11: Extra guida zincata per esterni in cataforesi (suppl. PER METRO) | D11: Metri | F11: 90 | H11: =F11*G11 -> 0
B12: Colonnino chiamate ai piani (cad.) | D12: Numero | F12: 120 | H12: =F12*G12 -> 0
B13: ACCESSORI
B14: Cadauna fermata intermedia (con scatola chiamata/rimando) | D14: Numero | F14: 450 | H14: =F14*G14 -> 0
B15: Comando acustico luminoso a bordo | D15: Consigliato | F15: 225 | H15: =F15*G15 -> 0
B16: Pulsantiera estensibile per accompagnatore | D16: Consigliato | F16: 300 | H16: =F16*G16 -> 0
B17: Ribaltamento meccanizzato piattaforma | D17: Consigliato | F17: 675 | H17: =F17*G17 -> 0
B18: Portata maggiorata (200 Kg) | D18: Compreso | F18: 0 | H18: =F18*G18 -> 0
B19: Trattamento in cataforesi completa telaio, motrice, piattaforma | D19: Compreso | F19: 0 | H19: =F19*G19 -> 0
B20: Colore RAL a scelta della pedana e guida | D20: +2 settimane | F20: 750 | H20: =F20*G20 -> 0
B21: Strapuntino ribaltabile | F21: 375 | H21: =F21*G21 -> 0
B22: Piattaforma 840x700 mm | F22: 150 | H22: =F22*G22 -> 0
B23: Piattaforma speciale su misura | F23: 375 | H23: =F23*G23 -> 0
B24: Bandella laterale mobile (SML) | F24: 375 | H24: =F24*G24 -> 0
B25: Telo di copertura (obbligatorio per impianti all'esterno) | F25: 375 | H25: =F25*G25 -> 0 | IT25: variato 02/03
B26: Rimando maniglione anticaduta lato salita sempre incluso nella base | D26: Compreso | F26: 0 | H26: =F26*G26 -> 0
B27: Gruppo soccorritore anti black-out | F27: 750 | H27: =F27*G27 -> 0
B28: SMONTAGGIO E SMALTIMENTO
B29: Smontaggio e smaltimento impianto preesistente | F29: 750 | H29: =F29*G29 -> 0
B30: TRASPORTO
B31: Trasporto incluso | F31: 400 | G31: 1 | H31: 0
B32: Imballo incluso | F32: 80 | G32: 1 | H32: 0
B33: MONTAGGIO
B34: Montaggio base incluso | F34: 850 | G34: 1 | H34: 0
B35: Ogni alzata | D35: Numero | F35: 25 | H35: =F35*G35 -> 0
B36: Ogni metro di guida (alzate fuori standard, rampe…) | D36: Numero | F36: 80 | H36: =F36*G36 -> 0
B37: Contributo per sopralluogo rilievi | F37: 300 | H37: =F37*G37 -> 0
B38: Trasporto nei centri storici con ZTL- zona blu | F38: 150 | H38: =F38*G38 -> 0
B40: Pacchetto Valore | F40: =G40*0.05*(SUM(H6:H29)+SUM(H35:H38)+F31+F32+F34) -> 0 | H40: 0
C42: PREZZO DI LISTINO | G42: =SUM(H6:H29)+SUM(H35:H38)+F31+F32+F34+F40 -> 9617.5
C44: PROMO | F44: 0.15 | G44: =-(G42*G45) -> 0 | H44: =IF(G45>15%,"ATTENZIONE!","")
G45: 0 | H45: =IF(G45>15%,"SUPERATO LO SCONTO MASSIMO","")
C47: PREZZO RISERVATO | G47: =G42*(1-G45) -> 9617.5 | H47: ="+ IVA 4% = "&G47*1.04 -> + IVA 4% = 10002,2

Sheet Facile Step SSC
B2: FACILE STEP (SSC curvilineo) | G2: N° OFFERTA | H2: #VALUE!
B5: DESCRIZIONE
B6: Piattaforma 840x650 ribaltabile manualmente, bandelle mobili automatiche, dispositivi di sicurezza | F6: 10062 | G6: 1 | H6: =F6*G6 -> 10062
B7: GUIDA
B8: Ogni alzata della scala | D8: Numero | F8: 78 | H8: =F8*G8 -> 0
B9: Ogni metro di guida (alzate fuori standard, rampe, ecc.) | D9: Metri | F9: 234 | H9: =F9*G9 -> 0
B10: Extra guida zincata per esterni in cataforesi (suppl. PER ALZATA) | D10: Numero | F10: 31.2 | H10: =F10*G10 -> 0
B11: Extra guida zincata per esterni in cataforesi (suppl. PER METRO) | D11: Metri | F11: 93.6 | H11: =F11*G11 -> 0
B12: Colonnino chiamate ai piani (cad.) | D12: Numero | F12: 124.8 | H12: =F12*G12 -> 0
B13: Curva a 90° (anche parcheggio) | D13: Numero | F13: 702 | H13: =F13*G13 -> 0
B14: Curva a 180° (anche parcheggio) max spessore inghiera 250mm | D14: Numero | F14: 904.8 | H14: =F14*G14 -> 0
B15: Curva zincata (supplemento cadauna) | D15: Numero | F15: 78 | H15: =F15*G15 -> 0
B16: ACCESSORI
B17: Cadauna fermata intermedia (con scatola chiamata/rimando) | F17: 468 | H17: =F17*G17 -> 0
B18: Gruppo soccorritore anti black-out | F18: 780 | H18: =F18*G18 -> 0
B19: Comando acustico luminoso a bordo | D19: Consigliato | F19: 234 | H19: =F19*G19 -> 0
B20: Pulsantiera estensibile per accompagnatore | D20: Consigliato | F20: 312 | H20: =F20*G20 -> 0
B21: Ribaltamento meccanizzato piattaforma | D21: Consigliato | F21: 702 | H21: =F21*G21 -> 0
B22: Rimando maniglione anticaduta lato salita sempre incluso nella base | D22: Compreso | F22: 0 | H22: =F22*G22 -> 0
B23: Portata maggiorata (200 Kg) | D23: Compreso | F23: 0 | H23: =F23*G23 -> 0
B24: Trattamento in CATAFORESI completa del telaio, motrice, piattaforma | D24: Compreso | F24: 0 | H24: =F24*G24 -> 0
B25: Colore RAL a richiesta pedana e binario | D25: +2 settimane | F25: 780 | H25: =F25*G25 -> 0
B26: Strapuntino ribaltabile | F26: 390 | H26: =F26*G26 -> 0
B27: Piattaforma 840x700 mm | F27: 156 | H27: =F27*G27 -> 0
B28: Piattaforma speciale su misura | F28: 390 | H28: =F28*G28 -> 0
B29: Bandella laterale mobile (SML) | F29: 390 | H29: =F29*G29 -> 0
B30: Telo di copertura (obbligatorio per impianti all'esterno) | F30: 390 | H30: =F30*G30 -> 0
B31: SMONTAGGIO E SMALTIMENTO
B32: Smontaggio e smaltimento impianto preesistente | F32: 1000 | H32: =F32*G32 -> 0
B33: TRASPORTO
B34: Trasporto incluso | F34: 400 | G34: 1 | H34: 0
B35: Imballo incluso | F35: 80 | G35: 1 | H35: 0
B36: MONTAGGIO
B37: Montaggio base incluso | F37: 1000 | G37: 1 | H37: 0
B38: Ogni alzata | D38: Numero | F38: 30 | H38: =F38*G38 -> 0
B39: Ogni metro di guida (alzate fuori standard, rampe…) | D39: Numero | F39: 100 | H39: =F39*G39 -> 0
B40: Ogni curva | D40: Numero | F40: 60 | H40: =F40*G40 -> 0
B41: Fermata intermedia (cad.) | D41: Numero | F41: 50 | H41: =F41*G41 -> 0
B42: Contributo per sopralluogo rilievi | F42: 300 | H42: =F42*G42 -> 0
B43: Trasporto nei centri storici con ZTL- zona blu | F43: 150 | H43: =F43*G43 -> 0
...

Sheet Facile Step X3
B2: FACILE STEP (X3 rettilineo) | G2: N° OFFERTA | H2: #VALUE!
B5: BASE IMPIANTO | H5: Totale Listino | V5: UM | X5: CALCOLO DEL PREZZO DELLA GUIDA
B6: 1 | C6: Prezzo Base Impianto | F6: 9245.6 | G6: 1 | H6: =F6*G6 -> 9245.6 | V6: m | W6: =ROUND('Facile Step X3'!G17,1) -> 1.8 | X6: diagonale naso-naso
B7: 1a | C7: Guida tagliata / forata a misura | F7: 267.8 | H7: =F7*G7 -> 0 | V7: € | W7: ='Facile Step X3'!AD12 -> 685 | X7: prezzo totale
B8: 2 | C8: Dimensioni Piattaforma: | F8: 0 | H8: =F8*G8 -> 0 | X8: composizione guida
C9: 640x680 | F9: 845 | H9: =F9*G9 -> 0 | V9: nr | W9: =VLOOKUP(ROUND('Facile Step X3'!$AC$12,1),'Facile Step X3'!$U$25:$AI$125,5,0) -> 1 | X9: sezione guida 1000
C10: 700X750 | F10: 0 | H10: =F10*G10 -> 0 | V10: nr | W10: =VLOOKUP(ROUND('Facile Step X3'!$AC$12,1),'Facile Step X3'!$U$25:$AI$125,6,0) -> 0 | X10: sezione guida 1400
C11: 800X800 | F11: 0 | H11: =F11*G11 -> 0 | V11: nr | W11: =VLOOKUP(ROUND('Facile Step X3'!$AC$12,1),'Facile Step X3'!$U$25:$AI$125,7,0) -> 0 | X11: sezione guida 1800 | AB11: Rail costs simulation | AD11: rail price
C12: 800x900 | F12: 0 | H12: =F12*G12 -> 0 | V12: nr | W12: =VLOOKUP(ROUND('Facile Step X3'!$AC$12,1),'Facile Step X3'!$U$25:$AI$125,8,0) -> 1 | X12: sezione guida 2200 | AB12: slope (m) | AC12: ='Facile Step X3'!W6 -> 1.8 | AD12: =VLOOKUP((ROUND(AC12,1)),U25:AI125,14,0) -> 685
C13: 800x1050 | F13: 469.3 | H13: =F13*G13 -> 0 | V13: nr | W13: =W9+W10+W11+W12 -> 2 | X13: numero di sezioni guida
C14: 800x1220 | F14: 469.3 | H14: =F14*G14 -> 0 | V14: nr | W14: =VLOOKUP(ROUND('Facile Step X3'!$AC$12,1),'Facile Step X3'!$U$25:$AI$125,12,0) -> 1 | X14: KIT giunzione
B15: 4 | C15: Piattaforma speciale | F15: 1553.5 | H15: =F15*G15 -> 0 | V15: nr | W15: =VLOOKUP(ROUND('Facile Step X3'!$AC$12,1),'Facile Step X3'!$U$25:$AI$125,13,0) -> 5 | X15: fissaggi guida inferiore
B16: GUIDE | V16: mm | W16: =VLOOKUP(ROUND('Facile Step X3'!$AC$12,1),'Facile Step X3'!$U$25:$AI$125,10,0) -> 100 | X16: Lunghezza eccedente
B17: 5 | C17: Corsa impianto (misura diagonale scala naso-naso) | E17: Metri | G17: 1.76 | H17: =F17*G17 -> 0 | V17: m | W17: =W6 -> 1.8 | X17: Lunghezza fissaggio a gradino
C18: Sezione guida 1,0m | F18: 247 | G18: ='Facile Step X3'!W9 -> 1 | H18: =F18*G18 -> 247 | V18: nr | W18: =VLOOKUP(W17,'Facile Step X3'!$U$25:$AI$125,15,0) -> 6 | X18: Numero di pilastrini
C19: Sezione guida 1,4m | F19: 339.3 | G19: ='Facile Step X3'!W10 -> 0 | H19: =F19*G19 -> 0 | V19: m | W19: =(VLOOKUP(ROUND('Facile Step X3'!$AC$12,1),'Facile Step X3'!$U$25:$AI$125,9,0))/1000 -> 3.2 | X19: Lunghezza totale guida
C20: Sezione guida 1,8m | F20: 431.6 | G20: ='Facile Step X3'!W11 -> 0 | H20: =F20*G20 -> 0
C21: Sezione guida 2,2m | F21: 525.2 | G21: ='Facile Step X3'!W12 -> 1 | H21: =F21*G21 -> 525.2 | Y21: rail section prices | AF21: splice price | AG21: bracket price
C22: Kit giunzione | F22: 79.3 | G22: ='Facile Step X3'!W14 -> 1 | H22: =F22*G22 -> 79.3 | Y22: 184 | Z22: 253 | AA22: 322 | AB22: 392 | AF22: 59 | AG22: 10
C23: Fissaggi guida inferiore | F23: 13 | G23: ='Facile Step X3'!W15 -> 5 | H23: =F23*G23 -> 65 | U23: 1 | V23: 2 | W23: 3 | X23: 4 | Y23: 5 | Z23: 6 | AA23: 7 | AB23: 8 | AC23: 9 | AD23: 10 | AE23: 11 | AF23: 12 | AG23: 13 | AH23: 14 | AI23: 15
B24: FISSAGGIO | U24: Slope to floor (m) | V24: slope (nose to nose) | W24: Travel (last nose to flor) | X24: required rail length | Y24: 1000 | Z24: 1400 | AA24: 1800 | AB24: 2200 | AC24: actual rail total length | AD24: rail length excess (mm) | AE24: q.ty of sections | AF24: q.ty of splices | AG24: bracket quantity | AH24: Total rail price | AI24: towers q.ty
B25: 6 | C25: Fissaggio a Muro | H25: =F25*G25 -> 0 | U25: \ | V25: 0 | W25: 0 | X25: 0 | AC25: 0 | AD25: 0 | AE25: 0 | AF25: 0 | AG25: 0 | AH25: 0 | AI25: 0
B26: 7 | C26: Fissaggio a Gradino | F26: 131 | H26: =G26*F26*'Facile Step X3'!W18 -> 0 | U26: 0 | V26: 0 | W26: 300 | X26: 1300 | Z26: 1 | AC26: 1400 | AD26: 100 | AE26: 1 | AF26: 0 | AG26: 3 | AH26: 283 | AI26: 3
B27: LAVORAZIONI E FINITURE | U27: 0.1 | V27: 100 | W27: 400 | X27: 1400 | Z27: 1 | AC27: 1400 | AD27: 0 | AE27: 1 | AF27: 0 | AG27: 3 | AH27: 283 | AI27: 3
B28: 8 | C28: Zincatura Pilastrini | F28: 33.8 | H28: =G28*F28*G26*'Facile Step X3'!W18 -> 0 | U28: 0.2 | V28: 200 | W28: 500 | X28: 1500 | AA28: 1 | AC28: 1800 | AD28: 300 | AE28: 1 | AF28: 0 | AG28: 3 | AH28: 352 | AI28: 3
B29: 9 | C29: Verniciatura sostegni RAL (a richiesta) | F29: 46.8 | H29: =G29*F29*G26*'Facile Step X3'!W18 -> 0 | U29: 0.3 | V29: 300 | W29: 600 | X29: 1600 | AA29: 1 | AC29: 1800 | AD29: 200 | AE29: 1 | AF29: 0 | AG29: 3 | AH29: 352 | AI29: 3
B30: 10 | C30: Verniciatura guida RAL (a richiesta) | F30: 829.4 | H30: =F30*G30 -> 0 | U30: 0.4 | V30: 400 | W30: 700 | X30: 1700 | AA30: 1 | AC30: 1800 | AD30: 100 | AE30: 1 | AF30: 0 | AG30: 3 | AH30: 352 | AI30: 4
B31: 11 | C31: Verniciatura Veicolo completo RAL (a richiesta) | F31: 1225.9 | H31: =F31*G31 -> 0 | U31: 0.5 | V31: 500 | W31: 800 | X31: 1800 | AA31: 1 | AC31: 1800 | AD31: 0 | AE31: 1 | AF31: 0 | AG31: 3 | AH31: 352 | AI31: 4
B32: OPTIONALS | U32: 0.6 | V32: 600 | W32: 900 | X32: 1900 | AB32: 1 | AC32: 2200 | AD32: 300 | AE32: 1 | AF32: 0 | AG32: 4 | AH32: 432 | AI32: 4
B33: 12 | C33: Pulsantiera Accompagnatore | E33: Numero | F33: 183.3 | H33: =F33*G33 -> 0 | U33: 0.7 | V33: 700 | W33: 1000 | X33: 2000 | AB33: 1 | AC33: 2200 | AD33: 200 | AE33: 1 | AF33: 0 | AG33: 4 | AH33: 432 | AI33: 4
B34: 13 | C34: Pilastrino per pulsantiera | E34: Numero | F34: 243.1 | H34: =F34*G34 -> 0 | U34: 0.8 | V34: 800 | W34: 1100 | X34: 2100 | AB34: 1 | AC34: 2200 | AD34: 100 | AE34: 1 | AF34: 0 | AG34: 4 | AH34: 432 | AI34: 4
B35: 14 | C35: Tettuccio copripulsantiera per impianti esterni | E35: Numero | F35: 39 | H35: =F35*G35 -> 0 | U35: 0.9 | V35: 900 | W35: 1200 | X35: 2200 | AB35: 1 | AC35: 2200 | AD35: 0 | AE35: 1 | AF35: 0 | AG35: 4 | AH35: 432 | AI35: 4
B36: 15 | C36: Tamponamenti PLEXIGLASS | E36: Metri | F36: 725.4 | H36: =F36*G36 -> 0 | U36: 1 | V36: 1000 | W36: 1300 | X36: 2300 | Y36: 1 | Z36: 1 | AC36: 2400 | AD36: 100 | AE36: 2 | AF36: 1 | AG36: 4 | AH36: 536 | AI36: 4
B37: 16 | C37: Seggiolino Imbottito | F37: 439.4 | H37: =F37*G37 -> 0 | U37: 1.1 | V37: 1100 | W37: 1400 | X37: 2400 | Y37: 1 | Z37: 1 | AC37: 2400 | AD37: 0 | AE37: 2 | AF37: 1 | AG37: 4 | AH37: 536 | AI37: 5
B38: 17 | C38: Prolunga per rampe | H38: =F38*G38 -> 0 | U38: 1.2 | V38: 1200 | W38: 1500 | X38: 2500 | Z38: 2 | AC38: 2800 | AD38: 300 | AE38: 2 | AF38: 1 | AG38: 4 | AH38: 605 | AI38: 5
C39: Destra | F39: 161.2 | H39: =F39*G39 -> 0 | U39: 1.3 | V39: 1300 | W39: 1600 | X39: 2600 | Z39: 2 | AC39: 2800 | AD39: 200 | AE39: 2 | AF39: 1 | AG39: 4 | AH39: 605 | AI39: 5
C40: Sinistra | F40: 161.2 | H40: =F40*G40 -> 0 | U40: 1.4 | V40: 1400 | W40: 1700 | X40: 2700 | Z40: 2 | AC40: 2800 | AD40: 100 | AE40: 2 | AF40: 1 | AG40: 5 | AH40: 615 | AI40: 5
B41: 18 | C41: Rampe fisse | H41: =F41*G41 -> 0 | U41: 1.5 | V41: 1500 | W41: 1800 | X41: 2800 | Z41: 2 | AC41: 2800 | AD41: 0 | AE41: 2 | AF41: 1 | AG41: 5 | AH41: 615 | AI41: 5
C42: Destra | F42: 161.2 | H42: =F42*G42 -> 0 | U42: 1.6 | V42: 1600 | W42: 1900 | X42: 2900 | Y42: 1 | AB42: 1 | AC42: 3200 | AD42: 300 | AE42: 2 | AF42: 1 | AG42: 5 | AH42: 685 | AI42: 5
C43: Sinistra | F43: 161.2 | H43: =F43*G43 -> 0 | U43: 1.7 | V43: 1700 | W43: 2000 | X43: 3000 | Y43: 1 | AB43: 1 | AC43: 3200 | AD43: 200 | AE43: 2 | AF43: 1 | AG43: 5 | AH43: 685 | AI43: 5
...

Sheet Facile Step ARTIRA
B2: FACILE STEP (ARTIRA curvilineo) | G2: N° OFFERTA | H2: #VALUE!
B5: BASE IMPIANTO
B6: 1 | C6: Tipo di scala | E6: Aggiungi nota
B7: 2 | C7: Posizione Impianto | E7: Seleziona | L7: Interno | O7: Trasparente | P7: Interno | Q7: Destro | R7: No
B8: 3 | C8: Lato impianto | E8: Seleziona | L8: Esterno | O8: Fumè | P8: Esterno | Q8: Sinistro | R8: Si
B9: 4 | C9: Configurazione impianto | E9: Aggiungi nota
B10: 5 | C10: Prezzo base impianto | F10: 12906.6 | G10: 1 | H10: =F10*G10 -> 12906.6 | L10: Sinistro
B11: 6 | C11: Dimensioni Piattaforma: | F11: 0 | L11: Destro
C12: 640x680 | F12: 504 | H12: =F12*G12 -> 0
C13: 700X750 | F13: 0 | H13: =F13*G13 -> 0
C14: 800X800 | F14: 0 | H14: =F14*G14 -> 0
C15: 800x900 | F15: 0 | H15: =F15*G15 -> 0
C16: 800x1050 | F16: 505.4 | H16: =F16*G16 -> 0
C17: 800x1220 | F17: 505.4 | H17: =F17*G17 -> 0
B18: 7 | C18: Caratteristiche Veicolo | E18: Aggiungi nota | F18: 0
B19: 8 | C19: Piattaforma speciale (da approvare) | F19: 2690.8 | H19: =F19*G19 -> 0
B20: 9 | C20: Piattaforma speciale CHIOCCIOLA (da approvare) | F20: 5486.6 | H20: =F20*G20 -> 0
B21: GUIDE
B22: 10 | C22: Corsa Impianto (Metro Binario) | E22: Metri | F22: 571.2 | H22: =F22*G22 -> 0
B23: 11 | C23: Partenza Veicolo | F23: 0
C24: Diritta | F24: 0 | H24: =F24*G24 -> 0
C25: Diritta Ridotta | F25: 546 | H25: =F25*G25 -> 0
C26: 90° | F26: 546 | H26: =F26*G26 -> 0
C27: 180° | F27: 702.8 | H27: =F27*G27 -> 0
C28: Speciale | F28: 905.8 | H28: =F28*G28 -> 0
B29: 12 | C29: Arrivo Veicolo | F29: 0
C30: Diritto | F30: 0 | H30: =F30*G30 -> 0
C31: 90° | F31: 546 | H31: =F31*G31 -> 0
C32: 180° | F32: 702.8 | H32: =F32*G32 -> 0
C33: Speciale | F33: 905.8 | H33: =F33*G33 -> 0
B34: 13 | C34: Curva di percorso a 180° | E34: Numero | F34: 702.8 | H34: =F34*G34 -> 0
B35: 14 | C35: Curva di percorso a 90° | E35: Numero | F35: 546 | H35: =F35*G35 -> 0
B36: 15 | C36: Curva di percorso a Pedoca (disegno speciale inviare photosurvey) | E36: Numero | F36: 1887.2 | H36: =F36*G36 -> 0
B37: 16 | C37: Curva Negativa (<90°) | E37: Numero | F37: 3190.6 | H37: =F37*G37 -> 0
B38: 17 | C38: Curva Raggio Variabile (disegno speciale inviare photosurvey) | E38: Numero | F38: 1785 | H38: =F38*G38 -> 0
B39: 18 | C39: Base Orizzontale - 3° Tubo (include 1m di percorso e i cambi di pendenza) | F39: 1010.8 | H39: =F39*G39 -> 0
B40: 19 | C40: Eccedenza Orizzontale - 3° Tubo | E40: Metri | F40: 240.8 | H40: =F40*G40 -> 0
B41: FISSAGGIO
B42: 20 | C42: Fissaggio a Muro | E42: Metri | F42: 63 | H42: =F42*G42 -> 0
B43: 21 | C43: Fissaggio a Muro con Contro-Piastre | E43: Metri | F43: 96.6 | H43: =F43*G43 -> 0
...
